Workbook

Sheet Livros Finalizados
A1: Nº | B1: Tipo | C1: Nome | D1: Autor | E1: Editora | F1: Gênero | G1: País | H1: Início | I1: Término | J1: Dias | K1: Formato | L1: Págs | M1: Nota
O3: Páginas | P3: Livros | Q3: HQs | R3: Mangás | S3: Físico | T3: Digital | U3: Total | V3: Relidos | W3: Média / P
A4: 190 | B4: Livro | C4: O Senhor dos Anéis | D4: J. R. R. Tolkien | E4: HarperCollins | F4: Fantasia | G4: Inglaterra | H4: 46123 | K4: Físico | L4: 1376 | O4: Total | P4: =SUMIFS(L:L,B:B,"Livro",I:I,">=01/01/2000",I:I,"<=31/12/2099") -> 45109 | Q4: =SUMIFS(L:L,B:B,"HQ",I:I,">=01/01/2000",I:I,"<=31/12/2099") -> 5812 | R4: =SUMIFS(L:L,B:B,"Mangá",I:I,">=01/01/2011",I:I,"<=31/12/2024") -> 664 | S4: =SUMIFS(L:L,K:K,"Físico",I:I,">=01/01/2000",I:I,"<=31/12/2099") -> 30837 | T4: =SUMIFS(L:L,K:K,"Digital",I:I,">=01/01/2000",I:I,"<=31/12/2099") -> 20748 | U4: =SUM(P4:R4) -> 51585 | V4: =COUNTIFS(C:C,"*(*",I:I,">=01/01/2000",I:I,"<=31/12/2099") -> 2 | W4: =SUM(W7:W22)/15 -> 9.4110348
A5: 189 | B5: Livro | C5: Se deus me chamar não vou | D5: Mariana Salomão Carrara | E5: Nós | F5: Romance de Formação | G5: Brasil | H5: 46304 | K5: Digital | L5: 116
A6: 188 | B6: Livro | C6: Matilda | D6: Roald Dahl | E6: Galera Júnior | F6: Fantasia | G6: Gales | H6: 46299 | I6: 46303 | J6: =IF(I6="", "", I6 - H6 + 1) -> 5 | K6: Digital | L6: 148 | M6: 4 | O6: Ano | P6: Livros | Q6: HQs | R6: Mangás | S6: Físico | T6: Digital | U6: Total | V6: Páginas | W6: Média / P
A7: 187 | B7: Livro | C7: Um jogador | D7: Fiódor Dostoiévski | E7: Editora 34 | F7: Romance Psicológico | G7: Rússia | H7: 46295 | I7: 46303 | J7: =IF(I7="", "", I7 - H7 + 1) -> 9 | K7: Físico | L7: 232 | M7: 4 | O7: 2011 | P7: =COUNTIFS(B:B,"Livro",I:I,">=01/01/2011",I:I,"<=31/12/2011") -> 2 | Q7: =COUNTIFS(B:B,"HQ",I:I,">=01/01/2011",I:I,"<=31/12/2011") -> 0 | R7: =COUNTIFS(B:B,"Mangá",I:I,">=01/01/2011",I:I,"<=31/12/2011") -> 0 | S7: =COUNTIFS(K:K,"Físico",I:I,">=01/01/2011",I:I,"<=31/12/2011") -> 2 | T7: =COUNTIFS(K:K,"Digital",I:I,">=01/01/2011",I:I,"<=31/12/2011") -> 0 | U7: =COUNTIFS(I:I,">=01/01/2011",I:I,"<=31/12/2011") -> 2 | V7: =SUMIFS(L:L,I:I,">=01/01/2011",I:I,"<=31/12/2011") -> 928 | W7: =V7/365 -> 2.5424658
A8: 186 | B8: Livro | C8: Ego transformado | D8: Timothy Keller | E8: Vida Nova | F8: Religião | G8: Estados Unidos | H8: 46293 | I8: 46296 | J8: =IF(I8="", "", I8 - H8 + 1) -> 4 | K8: Físico | L8: 112 | M8: 4 | O8: 2012 | P8: =COUNTIFS(B:B,"Livro",I:I,">=01/01/2012",I:I,"<=31/12/2012") -> 2 | Q8: =COUNTIFS(B:B,"HQ",I:I,">=01/01/2012",I:I,"<=31/12/2012") -> 0 | R8: =COUNTIFS(B:B,"Mangá",I:I,">=01/01/2012",I:I,"<=31/12/2012") -> 0 | S8: =COUNTIFS(K:K,"Físico",I:I,">=01/01/2012",I:I,"<=31/12/2012") -> 2 | T8: =COUNTIFS(K:K,"Digital",I:I,">=01/01/2012",I:I,"<=31/12/2012") -> 0 | U8: =COUNTIFS(I:I,">=01/01/2012",I:I,"<=31/12/2012") -> 2 | V8: =SUMIFS(L:L,I:I,">=01/01/2012",I:I,"<=31/12/2012") -> 616 | W8: =V8/366 -> 1.6830601
A9: 185 | B9: Livro | C9: Felicidade conjugal | D9: Liev Tolstói | E9: Nanofágica | F9: Romance Romântico | G9: Rússia | H9: 46287 | I9: 46291 | J9: =IF(I9="", "", I9 - H9 + 1) -> 5 | K9: Físico | L9: 144 | M9: 4 | O9: 2013 | P9: =COUNTIFS(B:B,"Livro",I:I,">=01/01/2013",I:I,"<=31/12/2013") -> 3 | Q9: =COUNTIFS(B:B,"HQ",I:I,">=01/01/2013",I:I,"<=31/12/2013") -> 0 | R9: =COUNTIFS(B:B,"Mangá",I:I,">=01/01/2013",I:I,"<=31/12/2013") -> 0 | S9: =COUNTIFS(K:K,"Físico",I:I,">=01/01/2013",I:I,"<=31/12/2013") -> 3 | T9: =COUNTIFS(K:K,"Digital",I:I,">=01/01/2013",I:I,"<=31/12/2013") -> 0 | U9: =COUNTIFS(I:I,">=01/01/2013",I:I,"<=31/12/2013") -> 3 | V9: =SUMIFS(L:L,I:I,">=01/01/2013",I:I,"<=31/12/2013") -> 823 | W9: =V9/365 -> 2.2547945
A10: 184 | B10: Livro | C10: Orgulho e Preconceito | D10: Jane Austen | E10: Zahar | F10: Romance de Formação | G10: Inglaterra | H10: 46266 | I10: 46284 | J10: =IF(I10="", "", I10 - H10 + 1) -> 19 | K10: Físico | L10: 368 | M10: 4.5 | O10: 2014 | P10: =COUNTIFS(B:B,"Livro",I:I,">=01/01/2014",I:I,"<=31/12/2014") -> 15 | Q10: =COUNTIFS(B:B,"HQ",I:I,">=01/01/2014",I:I,"<=31/12/2014") -> 0 | R10: =COUNTIFS(B:B,"Mangá",I:I,">=01/01/2014",I:I,"<=31/12/2014") -> 0 | S10: =COUNTIFS(K:K,"Físico",I:I,">=01/01/2014",I:I,"<=31/12/2014") -> 15 | T10: =COUNTIFS(K:K,"Digital",I:I,">=01/01/2014",I:I,"<=31/12/2014") -> 0 | U10: =COUNTIFS(I:I,">=01/01/2014",I:I,"<=31/12/2014") -> 15 | V10: =SUMIFS(L:L,I:I,">=01/01/2014",I:I,"<=31/12/2014") -> 3462 | W10: =V10/365 -> 9.4849315
A11: 183 | B11: Livro | C11: O signo dos quatro | D11: Arthur Conan Doyle | E11: Zahar | F11: Romance Policial | G11: Escócia | H11: 46263 | I11: 46272 | J11: =IF(I11="", "", I11 - H11 + 1) -> 10 | K11: Físico | L11: 184 | M11: 4 | O11: 2015 | P11: =COUNTIFS(B:B,"Livro",I:I,">=01/01/2015",I:I,"<=31/12/2015") -> 1 | Q11: =COUNTIFS(B:B,"HQ",I:I,">=01/01/2015",I:I,"<=31/12/2015") -> 1 | R11: =COUNTIFS(B:B,"Mangá",I:I,">=01/01/2015",I:I,"<=31/12/2015") -> 0 | S11: =COUNTIFS(K:K,"Físico",I:I,">=01/01/2015",I:I,"<=31/12/2015") -> 2 | T11: =COUNTIFS(K:K,"Digital",I:I,">=01/01/2015",I:I,"<=31/12/2015") -> 0 | U11: =COUNTIFS(I:I,">=01/01/2015",I:I,"<=31/12/2015") -> 2 | V11: =SUMIFS(L:L,I:I,">=01/01/2015",I:I,"<=31/12/2015") -> 482 | W11: =V11/365 -> 1.3205479
A12: 182 | B12: Livro | C12: O adversário secreto | D12: Agatha Christie | E12: Globo Livros | F12: Romance Policial | G12: Inglaterra | H12: 46248 | I12: 46266 | J12: =IF(I12="", "", I12 - H12 + 1) -> 19 | K12: Físico | L12: 382 | M12: 4.5 | O12: 2016 | P12: =COUNTIFS(B:B,"Livro",I:I,">=01/01/2016",I:I,"<=31/12/2016") -> 0 | Q12: =COUNTIFS(B:B,"HQ",I:I,">=01/01/2016",I:I,"<=31/12/2016") -> 10 | R12: =COUNTIFS(B:B,"Mangá",I:I,">=01/01/2016",I:I,"<=31/12/2016") -> 0 | S12: =COUNTIFS(K:K,"Físico",I:I,">=01/01/2016",I:I,"<=31/12/2016") -> 10 | T12: =COUNTIFS(K:K,"Digital",I:I,">=01/01/2016",I:I,"<=31/12/2016") -> 0 | U12: =COUNTIFS(I:I,">=01/01/2016",I:I,"<=31/12/2016") -> 10 | V12: =SUMIFS(L:L,I:I,">=01/01/2016",I:I,"<=31/12/2016") -> 2216 | W12: =V12/366 -> 6.0546448
A13: 181 | B13: Livro | C13: O Evangelho Maltrapilho | D13: Brennan Manning | E13: Mundo Cristão | F13: Religião | G13: Estados Unidos | H13: 46215 | I13: 46258 | J13: =IF(I13="", "", I13 - H13 + 1) -> 44 | K13: Digital | L13: 213 | M13: 4 | O13: 2017 | P13: =COUNTIFS(B:B,"Livro",I:I,">=01/01/2017",I:I,"<=31/12/2017") -> 3 | Q13: =COUNTIFS(B:B,"HQ",I:I,">=01/01/2017",I:I,"<=31/12/2017") -> 1 | R13: =COUNTIFS(B:B,"Mangá",I:I,">=01/01/2017",I:I,"<=31/12/2017") -> 0 | S13: =COUNTIFS(K:K,"Físico",I:I,">=01/01/2017",I:I,"<=31/12/2017") -> 4 | T13: =COUNTIFS(K:K,"Digital",I:I,">=01/01/2017",I:I,"<=31/12/2017") -> 0 | U13: =COUNTIFS(I:I,">=01/01/2017",I:I,"<=31/12/2017") -> 4 | V13: =SUMIFS(L:L,I:I,">=01/01/2017",I:I,"<=31/12/2017") -> 490 | W13: =V13/365 -> 1.3424658
A14: 180 | B14: Livro | C14: Deuses americanos | D14: Neil Gaiman | E14: Intrínseca | F14: Fantasia | G14: Inglaterra | H14: 46204 | I14: 46240 | J14: =IF(I14="", "", I14 - H14 + 1) -> 37 | K14: Digital | L14: 762 | M14: 3.5 | O14: 2018 | P14: =COUNTIFS(B:B,"Livro",I:I,">=01/01/2018",I:I,"<=31/12/2018") -> 0 | Q14: =COUNTIFS(B:B,"HQ",I:I,">=01/01/2018",I:I,"<=31/12/2018") -> 0 | R14: =COUNTIFS(B:B,"Mangá",I:I,">=01/01/2018",I:I,"<=31/12/2018") -> 0 | S14: =COUNTIFS(K:K,"Físico",I:I,">=01/01/2018",I:I,"<=31/12/2018") -> 0 | T14: =COUNTIFS(K:K,"Digital",I:I,">=01/01/2018",I:I,"<=31/12/2018") -> 0 | U14: =COUNTIFS(I:I,">=01/01/2018",I:I,"<=31/12/2018") -> 0 | V14: =SUMIFS(L:L,I:I,">=01/01/2018",I:I,"<=31/12/2018") -> 0 | W14: =V14/365 -> 0
A15: 179 | B15: Livro | C15: Maravilhosa Graça | D15: C. H. Spurgeon | E15: Oxigênio | F15: Religião | G15: Inglaterra | H15: 46221 | I15: 46222 | J15: =IF(I15="", "", I15 - H15 + 1) -> 2 | K15: Digital | L15: 39 | M15: 4 | O15: 2019 | P15: =COUNTIFS(B:B,"Livro",I:I,">=01/01/2019",I:I,"<=31/12/2019") -> 7 | Q15: =COUNTIFS(B:B,"HQ",I:I,">=01/01/2019",I:I,"<=31/12/2019") -> 0 | R15: =COUNTIFS(B:B,"Mangá",I:I,">=01/01/2019",I:I,"<=31/12/2019") -> 0 | S15: =COUNTIFS(K:K,"Físico",I:I,">=01/01/2019",I:I,"<=31/12/2019") -> 0 | T15: =COUNTIFS(K:K,"Digital",I:I,">=01/01/2019",I:I,"<=31/12/2019") -> 7 | U15: =COUNTIFS(I:I,">=01/01/2019",I:I,"<=31/12/2019") -> 7 | V15: =SUMIFS(L:L,I:I,">=01/01/2019",I:I,"<=31/12/2019") -> 2087 | W15: =V15/365 -> 5.7178082
A16: 178 | B16: Livro | C16: Jesus Copy | D16: Douglas Gonçalves | E16: Mundo Cristão | F16: Religião | G16: Brasil | H16: 46211 | I16: 46212 | J16: =IF(I16="", "", I16 - H16 + 1) -> 2 | K16: Digital | L16: 153 | M16: 4.5 | O16: 2020 | P16: =COUNTIFS(B:B,"Livro",I:I,">=01/01/2020",I:I,"<=31/12/2020") -> 0 | Q16: =COUNTIFS(B:B,"HQ",I:I,">=01/01/2020",I:I,"<=31/12/2020") -> 0 | R16: =COUNTIFS(B:B,"Mangá",I:I,">=01/01/2020",I:I,"<=31/12/2020") -> 0 | S16: =COUNTIFS(K:K,"Físico",I:I,">=01/01/2020",I:I,"<=31/12/2020") -> 0 | T16: =COUNTIFS(K:K,"Digital",I:I,">=01/01/2020",I:I,"<=31/12/2020") -> 0 | U16: =COUNTIFS(I:I,">=01/01/2020",I:I,"<=31/12/2020") -> 0 | V16: =SUMIFS(L:L,I:I,">=01/01/2020",I:I,"<=31/12/2020") -> 0 | W16: =V16/366 -> 0
A17: 177 | B17: Livro | C17: A metamorfose | D17: Franz Kafka | E17: Antofágica | F17: Fantástico | G17: República Tcheca | H17: 46192 | I17: 46197 | J17: =IF(I17="", "", I17 - H17 + 1) -> 6 | K17: Físico | L17: 232 | M17: 4 | O17: 2021 | P17: =COUNTIFS(B:B,"Livro",I:I,">=01/01/2021",I:I,"<=31/12/2021") -> 1 | Q17: =COUNTIFS(B:B,"HQ",I:I,">=01/01/2021",I:I,"<=31/12/2021") -> 0 | R17: =COUNTIFS(B:B,"Mangá",I:I,">=01/01/2021",I:I,"<=31/12/2021") -> 0 | S17: =COUNTIFS(K:K,"Físico",I:I,">=01/01/2021",I:I,"<=31/12/2021") -> 1 | T17: =COUNTIFS(K:K,"Digital",I:I,">=01/01/2021",I:I,"<=31/12/2021") -> 0 | U17: =COUNTIFS(I:I,">=01/01/2021",I:I,"<=31/12/2021") -> 1 | V17: =SUMIFS(L:L,I:I,">=01/01/2021",I:I,"<=31/12/2021") -> 352 | W17: =V17/365 -> 0.96438356
A18: 176 | B18: Livro | C18: O último dia de um condenado | D18: Victor Hugo | E18: Nanofágica | F18: Romance Social | G18: França | H18: 46180 | I18: 46188 | J18: =IF(I18="", "", I18 - H18 + 1) -> 9 | K18: Digital | L18: 118 | M18: 4.5 | O18: 2022 | P18: =COUNTIFS(B:B,"Livro",I:I,">=01/01/2022",I:I,"<=31/12/2022") -> 7 | Q18: =COUNTIFS(B:B,"HQ",I:I,">=01/01/2022",I:I,"<=31/12/2022") -> 0 | R18: =COUNTIFS(B:B,"Mangá",I:I,">=01/01/2022",I:I,"<=31/12/2022") -> 0 | S18: =COUNTIFS(K:K,"Físico",I:I,">=01/01/2022",I:I,"<=31/12/2022") -> 7 | T18: =COUNTIFS(K:K,"Digital",I:I,">=01/01/2022",I:I,"<=31/12/2022") -> 0 | U18: =COUNTIFS(I:I,">=01/01/2022",I:I,"<=31/12/2022") -> 7 | V18: =SUMIFS(L:L,I:I,">=01/01/2022",I:I,"<=31/12/2022") -> 2165 | W18: =V18/365 -> 5.9315068
A19: 175 | B19: Livro | C19: O que resta de nós | D19: Virginie Grimaldi | E19: Gutenberg | F19: Romance Contemporâneo | G19: França | H19: 46175 | I19: 46186 | J19: =IF(I19="", "", I19 - H19 + 1) -> 12 | K19: Digital | L19: 230 | M19: 4 | O19: 2023 | P19: =COUNTIFS(B:B,"Livro",I:I,">=01/01/2023",I:I,"<=31/12/2023") -> 0 | Q19: =COUNTIFS(B:B,"HQ",I:I,">=01/01/2023",I:I,"<=31/12/2023") -> 0 | R19: =COUNTIFS(B:B,"Mangá",I:I,">=01/01/2023",I:I,"<=31/12/2023") -> 0 | S19: =COUNTIFS(K:K,"Físico",I:I,">=01/01/2023",I:I,"<=31/12/2023") -> 0 | T19: =COUNTIFS(K:K,"Digital",I:I,">=01/01/2023",I:I,"<=31/12/2023") -> 0 | U19: =COUNTIFS(I:I,">=01/01/2023",I:I,"<=31/12/2023") -> 0 | V19: =SUMIFS(L:L,I:I,">=01/01/2023",I:I,"<=31/12/2023") -> 0 | W19: =V19/365 -> 0
A20: 174 | B20: Livro | C20: Madame Bovary | D20: Gustave Flaubert | E20: Penguin | F20: Romance Psicológico | G20: França | H20: 46144 | I20: 46179 | J20: =IF(I20="", "", I20 - H20 + 1) -> 36 | K20: Digital | L20: 448 | M20: 3.5 | O20: 2024 | P20: =COUNTIFS(B:B,"Livro",I:I,">=01/01/2024",I:I,"<=31/12/2024") -> 54 | Q20: =COUNTIFS(B:B,"HQ",I:I,">=01/01/2024",I:I,"<=31/12/2024") -> 15 | R20: =COUNTIFS(B:B,"Mangá",I:I,">=01/01/2024",I:I,"<=31/12/2024") -> 3 | S20: =COUNTIFS(K:K,"Físico",I:I,">=01/01/2024",I:I,"<=31/12/2024") -> 36 | T20: =COUNTIFS(K:K,"Digital",I:I,">=01/01/2024",I:I,"<=31/12/2024") -> 36 | U20: =COUNTIFS(I:I,">=01/01/2024",I:I,"<=31/12/2024") -> 72 | V20: =SUMIFS(L:L,I:I,">=01/01/2024",I:I,"<=31/12/2024") -> 18976 | W20: =V20/366 -> 51.846995
A21: 173 | B21: Livro | C21: 12 Regras Para a Vida: Um Antídoto Para o Caos | D21: Jordan B. Peterson | E21: Alta Books | F21: Psicologia | G21: Canadá | H21: 46067 | I21: 46163 | J21: =IF(I21="", "", I21 - H21 + 1) -> 97 | K21: Digital | L21: 554 | M21: 4 | O21: 2025 | P21: =COUNTIFS(B:B,"Livro",I:I,">=01/01/2025",I:I,"<=31/12/2025") -> 36 | Q21: =COUNTIFS(B:B,"HQ",I:I,">=01/01/2025",I:I,"<=31/12/2025") -> 0 | R21: =COUNTIFS(B:B,"Mangá",I:I,">=01/01/2025",I:I,"<=31/12/2025") -> 0 | S21: =COUNTIFS(K:K,"Físico",I:I,">=01/01/2025",I:I,"<=31/12/2025") -> 18 | T21: =COUNTIFS(K:K,"Digital",I:I,">=01/01/2025",I:I,"<=31/12/2025") -> 18 | U21: =COUNTIFS(I:I,">=01/01/2025",I:I,"<=31/12/2025") -> 36 | V21: =SUMIFS(L:L,I:I,">=01/01/2025",I:I,"<=31/12/2025") -> 12409 | W21: =V21/365 -> 33.99726
A22: 172 | B22: Livro | C22: Um Coração Simples | D22: Gustave Flaubert | E22: Grua | F22: Contos | G22: França | H22: 46146 | I22: 46146 | J22: =IF(I22="", "", I22 - H22 + 1) -> 1 | K22: Físico | L22: 80 | M22: 3.5 | O22: 2026 | P22: =COUNTIFS(B:B,"Livro",I:I,">=01/01/2026",I:I,"<=31/12/2026") -> 27 | Q22: =COUNTIFS(B:B,"HQ",I:I,">=01/01/2026",I:I,"<=31/12/2026") -> 0 | R22: =COUNTIFS(B:B,"Mangá",I:I,">=01/01/2026",I:I,"<=31/12/2026") -> 0 | S22: =COUNTIFS(K:K,"Físico",I:I,">=01/01/2026",I:I,"<=31/12/2026") -> 14 | T22: =COUNTIFS(K:K,"Digital",I:I,">=01/01/2026",I:I,"<=31/12/2026") -> 13 | U22: =COUNTIFS(I:I,">=01/01/2026",I:I,"<=31/12/2026") -> 27 | V22: =SUMIFS(L:L,I:I,">=01/01/2026",I:I,"<=31/12/2026") -> 6579 | W22: =V22/365 -> 18.024658
A23: 171 | B23: Livro | C23: Sonhos de Trem | D23: Denis Johnson | E23: Companhia das Letras | F23: Romance Histórico | G23: Estados Unidos | H23: 46134 | I23: 46140 | J23: =IF(I23="", "", I23 - H23 + 1) -> 7 | K23: Digital | L23: 81 | M23: 2
A24: 170 | B24: Livro | C24: Romeu e Julieta | D24: William Shakespeare | E24: Principis | F24: Teatro | G24: Inglaterra | H24: 46128 | I24: 46130 | J24: =IF(I24="", "", I24 - H24 + 1) -> 3 | K24: Físico | L24: 128 | M24: 3.5 | O24: Quantia | P24: Livros | Q24: HQs | R24: Mangás | S24: Físico | T24: Digital | U24: Total | V24: Páginas | W24: Média / L
A25: 169 | B25: Livro | C25: Romeu & Julieta | D25: William Shakespeare | E25: Antofágica | F25: Teatro | G25: Inglaterra | H25: 46120 | I25: 46130 | J25: =IF(I25="", "", I25 - H25 + 1) -> 11 | K25: Físico | L25: 240 | M25: 3.5 | O25: Total | P25: =SUM(P7:P22) -> 158 | Q25: =SUM(Q7:Q22) -> 27 | R25: =SUM(R7:R22) -> 3 | S25: =SUM(S7:S22) -> 114 | T25: =SUM(T7:T22) -> 74 | U25: =SUM(U7:U22) -> 188 | V25: =SUM(V7:V22) -> 51585 | W25: =SUM(U25)/16 -> 11.75
A26: 168 | B26: Livro | C26: Harry Potter e o Cálice de Fogo | D26: J. K. Rowling | E26: Rocco Karl James | F26: Fantasia | G26: Inglaterra | H26: 46023 | I26: 46118 | J26: =IF(I26="", "", I26 - H26 + 1) -> 96 | K26: Físico | L26: 608 | M26: 4.5
A27: 167 | B27: Livro | C27: Em seus passos o que faria Jesus? | D27: Charles M. Sheldon | E27: Mundo Cristão | F27: Romance Religioso | G27: Estados Unidos | H27: 46084 | I27: 46094 | J27: =IF(I27="", "", I27 - H27 + 1) -> 11 | K27: Digital | L27: 251 | M27: 4 | O27: Mês | P27: Total | R27: Nota | S27: Tipo | T27: Nº
A28: 166 | B28: Livro | C28: Os doze mandamentos | D28: Sidney Sheldon | E28: Record | F28: Sátira | G28: Estados Unidos | H28: 46082 | I28: 46089 | J28: =IF(I28="", "", I28 - H28 + 1) -> 8 | K28: Digital | L28: 113 | M28: 2.5 | O28: Janeiro | P28: =SUMPRODUCT((MONTH(I2:I924)=1)*(I2:I924<>"")) -> 11 | R28: 5 | S28: Perfeito | T28: =COUNTIF(M:M,5) -> 36
A29: 165 | B29: Livro | C29: O cavaleiro inexistente | D29: Italo Calvino | E29: Companhia de Bolso | F29: Fantasia | G29: Itália | H29: 46076 | I29: 46081 | J29: =IF(I29="", "", I29 - H29 + 1) -> 6 | K29: Digital | L29: 119 | M29: 3 | O29: Fevereiro | P29: =SUMPRODUCT(--(MONTH(I2:I924)=2)) -> 8 | R29: 4.5 | S29: Incrível | T29: =COUNTIF(M:M,4.5) -> 16
A30: 164 | B30: Livro | C30: Cartas de um diabo a seu aprendiz | D30: C. S. Lewis | E30: Thomas Nelson Brasil | F30: Religião | G30: Irlanda do Norte | H30: 46069 | I30: 46073 | J30: =IF(I30="", "", I30 - H30 + 1) -> 5 | K30: Físico | L30: 208 | M30: 4 | O30: Março | P30: =SUMPRODUCT(--(MONTH(I2:I924)=3)) -> 10 | R30: 4 | S30: Ótimo | T30: =COUNTIF(M:M,4) -> 90
A31: 163 | B31: Livro | C31: Convite para um homicídio | D31: Agatha Christie | E31: HarperCollins | F31: Romance Policial | G31: Inglaterra | H31: 46032 | I31: 46046 | J31: =IF(I31="", "", I31 - H31 + 1) -> 15 | K31: Físico | L31: 272 | M31: 4 | O31: Abril | P31: =SUMPRODUCT(--(MONTH(I2:I924)=4)) -> 9 | R31: 3.5 | S31: Bom | T31: =COUNTIF(M:M,3.5) -> 12
A32: 162 | B32: Livro | C32: Meditações | D32: Marco Aurélio | E32: Edipro | F32: Filosofia | G32: Roma Antiga | H32: 46020 | I32: 46045 | J32: =IF(I32="", "", I32 - H32 + 1) -> 26 | K32: Físico | L32: 160 | M32: 4.5 | O32: Maio | P32: =SUMPRODUCT(--(MONTH(I2:I924)=5)) -> 22 | R32: 3 | S32: Decente | T32: =COUNTIF(M:M,3) -> 25
A33: 161 | B33: Livro | C33: Uma canção de natal | D33: Charles Dickens | E33: Penguin | F33: Fantasia | G33: Inglaterra | H33: 46013 | I33: 46019 | J33: =IF(I33="", "", I33 - H33 + 1) -> 7 | K33: Digital | L33: 156 | M33: 4 | O33: Junho | P33: =SUMPRODUCT(--(MONTH(I2:I924)=6)) -> 31 | R33: 2.5 | S33: Fraco | T33: =COUNTIF(M:M,2.5) -> 4
A34: 160 | B34: Livro | C34: As cinco pessoas que você encontra no céu | D34: Mitch Albom | E34: Sextante | F34: Fantasia | G34: Estados Unidos | H34: 46010 | I34: 46013 | J34: =IF(I34="", "", I34 - H34 + 1) -> 4 | K34: Digital | L34: 200 | M34: 3 | O34: Julho | P34: =SUMPRODUCT(--(MONTH(I2:I924)=7)) -> 23 | R34: 2 | S34: Ruim | T34: =COUNTIF(M:M,2) -> 5
A35: 159 | B35: Livro | C35: O homem mais rico da Babilônia | D35: George S. Clason | E35: HarperCollins | F35: Finanças | G35: Estados Unidos | H35: 46007 | I35: 46009 | J35: =IF(I35="", "", I35 - H35 + 1) -> 3 | K35: Físico | L35: 160 | M35: 4 | O35: Agosto | P35: =SUMPRODUCT(--(MONTH(I2:I924)=8)) -> 14 | R35: 1.5 | S35: Péssimo | T35: =COUNTIF(M:M,1.5) -> 0
A36: 158 | B36: Livro | C36: O Meu Pé de Laranja Lima | D36: José Mauro de Vasconcelos | E36: Melhoramentos | F36: Romance de Formação | G36: Brasil | H36: 46001 | I36: 46006 | J36: =IF(I36="", "", I36 - H36 + 1) -> 6 | K36: Físico | L36: 232 | M36: 5 | O36: Setembro | P36: =SUMPRODUCT(--(MONTH(I2:I924)=9)) -> 14 | R36: 1 | S36: Horrível | T36: =COUNTIF(M:M,1) -> 0
A37: 157 | B37: Livro | C37: O homem mais feliz do mundo | D37: Eddie Jaku | E37: Intrínseca | F37: Biografia | G37: Austrália | H37: 45997 | I37: 46001 | J37: =IF(I37="", "", I37 - H37 + 1) -> 5 | K37: Digital | L37: 149 | M37: 4.5 | O37: Outubro | P37: =SUMPRODUCT(--(MONTH(I2:I924)=10)) -> 11 | R37: - | S37: Total | T37: =SUM(T28:T36) -> 188
A38: 156 | B38: Livro | C38: Segredo de justiça | D38: Andréa Pachá | E38: Intrínseca | F38: Crônicas | G38: Brasil | H38: 45972 | I38: 46001 | J38: =IF(I38="", "", I38 - H38 + 1) -> 30 | K38: Digital | L38: 220 | M38: 4 | O38: Novembro | P38: =SUMPRODUCT(--(MONTH(I2:I924)=11)) -> 19
A39: 155 | B39: Livro | C39: Entendes o que lês? | D39: Gordon Fee | Douglas Stuart | E39: Vida Nova | F39: Religião | G39: Estados Unidos | H39: 45967 | I39: 45990 | J39: =IF(I39="", "", I39 - H39 + 1) -> 24 | K39: Físico | L39: 414 | M39: 3.5 | O39: Dezembro | P39: =SUMPRODUCT(--(MONTH(I2:I924)=12)) -> 16
A40: 154 | B40: Livro | C40: A Dama das Camélias | D40: Alexandre Dumas Filho | E40: Martin Claret | F40: Romance Romântico | G40: França | H40: 45973 | I40: 45980 | J40: =IF(I40="", "", I40 - H40 + 1) -> 8 | K40: Físico | L40: 291 | M40: 5 | O40: Total | P40: =SUM(P28:P39) -> 188
A41: 153 | B41: Livro | C41: Olhai os lírios do campo | D41: Erico Verissimo | E41: Companhia das Letras | F41: Romance Social | G41: Brasil | H41: 45899 | I41: 45966 | J41: =IF(I41="", "", I41 - H41 + 1) -> 68 | K41: Digital | L41: 418 | M41: 4
...

Sheet Leitura Conjunta - Diana
A1: Nº | B1: Tipo | C1: Nome | D1: Autor | E1: Editora | F1: Indicação | G1: Início | H1: Término | I1: Dias | J1: Formato | K1: Páginas | L1: NL | M1: ND | N1: Nota
P3: Páginas | Q3: Livros | R3: HQs | S3: Mangás | T3: Físico | U3: Digital | V3: Total | W3: Relidos | X3: Média / P
A4: 25 | B4: Livro | C4: Matilda | D4: Roald Dahl | E4: Galera Júnior | F4: Diana | G4: 46299 | H4: 46303 | I4: =IF(H4="", "", H4 - G4 + 1) -> 5 | J4: Digital | K4: 148 | L4: 4 | M4: 4 | N4: =ROUND(AVERAGE(L4:M4)*2,0)/2 -> 4 | P4: Total | Q4: =SUMIFS(K:K,B:B,"Livro",H:H,">=01/01/2000",H:H,"<=31/12/2099") -> 8518 | R4: =SUMIFS(K:K,B:B,"HQ",H:H,">=01/01/2000",H:H,"<=31/12/2099") -> 0 | S4: =SUMIFS(K:K,B:B,"Mangá",H:H,">=01/01/2011",H:H,"<=31/12/2024") -> 0 | T4: =SUMIFS(K:K,J:J,"Físico",H:H,">=01/01/2000",H:H,"<=31/12/2099") -> 7129 | U4: =SUMIFS(K:K,J:J,"Digital",H:H,">=01/01/2000",H:H,"<=31/12/2099") -> 1389 | V4: =SUM(Q4:S4) -> 8518 | W4: =COUNTIFS(C:C,"*(*",H:H,">=01/01/2000",H:H,"<=31/12/2099") -> 0 | X4: =SUM(X7:X9)/2 -> 11.662235
A5: 24 | B5: Livro | C5: Orgulho e Preconceito | D5: Jane Austen | E5: Zahar | F5: Diana | G5: 46266 | H5: 46284 | I5: =IF(H5="", "", H5 - G5 + 1) -> 19 | J5: Físico | K5: 368 | L5: 4.5 | M5: 4 | N5: =ROUND(AVERAGE(L5:M5)*2,0)/2 -> 4.5
A6: 23 | B6: Livro | C6: O adversário secreto | D6: Agatha Christie | E6: Globo Livros | F6: Diana | G6: 46248 | H6: 46266 | I6: =IF(H6="", "", H6 - G6 + 1) -> 19 | J6: Físico | K6: 382 | L6: 4.5 | M6: 4.5 | N6: =ROUND(AVERAGE(L6:M6)*2,0)/2 -> 4.5 | P6: Ano | Q6: Livros | R6: HQs | S6: Mangás | T6: Físico | U6: Digital | V6: Total | W6: Páginas | X6: Média / P
A7: 22 | B7: Livro | C7: A metamorfose | D7: Franz Kafka | E7: Antofágica | F7: Diana | G7: 46192 | H7: 46197 | I7: =IF(H7="", "", H7 - G7 + 1) -> 6 | J7: Físico | K7: 232 | L7: 4 | M7: 4 | N7: =ROUND(AVERAGE(L7:M7)*2,0)/2 -> 4 | P7: 2024 | Q7: =COUNTIFS(B:B,"Livro",H:H,">=01/01/2024",H:H,"<=31/12/2024") -> 5 | R7: =COUNTIFS(B:B,"HQ",H:H,">=01/01/2024",H:H,"<=31/12/2024") -> 0 | S7: =COUNTIFS(B:B,"Mangá",H:H,">=01/01/2024",H:H,"<=31/12/2024") -> 0 | T7: =COUNTIFS(J:J,"Físico",H:H,">=01/01/2024",H:H,"<=31/12/2024") -> 5 | U7: =COUNTIFS(J:J,"Digital",H:H,">=01/01/2024",H:H,"<=31/12/2024") -> 0 | V7: =COUNTIFS(H:H,">=01/01/2024",H:H,"<=31/12/2024") -> 5 | W7: =SUMIFS(K:K,H:H,">=01/01/2024",H:H,"<=31/12/2024") -> 1672 | X7: =W7/366 -> 4.568306
A8: 21 | B8: Livro | C8: O último dia de um condenado | D8: Victor Hugo | E8: Antofágica | F8: Diana | G8: 46180 | H8: 46188 | I8: =IF(H8="", "", H8 - G8 + 1) -> 9 | J8: Digital | K8: 118 | L8: 4.5 | M8: 4.5 | N8: =ROUND(AVERAGE(L8:M8)*2,0)/2 -> 4.5 | P8: 2025 | Q8: =COUNTIFS(B:B,"Livro",H:H,">=01/01/2025",H:H,"<=31/12/2025") -> 9 | R8: =COUNTIFS(B:B,"HQ",H:H,">=01/01/2025",H:H,"<=31/12/2025") -> 0 | S8: =COUNTIFS(B:B,"Mangá",H:H,">=01/01/2025",H:H,"<=31/12/2025") -> 0 | T8: =COUNTIFS(J:J,"Físico",H:H,">=01/01/2025",H:H,"<=31/12/2025") -> 7 | U8: =COUNTIFS(J:J,"Digital",H:H,">=01/01/2025",H:H,"<=31/12/2025") -> 2 | V8: =COUNTIFS(H:H,">=01/01/2025",H:H,"<=31/12/2025") -> 9 | W8: =SUMIFS(K:K,H:H,">=01/01/2025",H:H,"<=31/12/2025") -> 4188 | X8: =W8/365 -> 11.473973
A9: 20 | B9: Livro | C9: Madame Bovary | D9: Gustave Flaubert | E9: Penguin | F9: Diana | G9: 46144 | H9: 46179 | I9: =IF(H9="", "", H9 - G9 + 1) -> 36 | J9: Digital | K9: 448 | L9: 3.5 | M9: 4.5 | N9: =ROUND(AVERAGE(L9:M9)*2,0)/2 -> 4 | P9: 2026 | Q9: =COUNTIFS(B:B,"Livro",H:H,">=01/01/2026",H:H,"<=31/12/2026") -> 11 | R9: =COUNTIFS(B:B,"HQ",H:H,">=01/01/2026",H:H,"<=31/12/2026") -> 0 | S9: =COUNTIFS(B:B,"Mangá",H:H,">=01/01/2026",H:H,"<=31/12/2026") -> 0 | T9: =COUNTIFS(J:J,"Físico",H:H,">=01/01/2026",H:H,"<=31/12/2026") -> 6 | U9: =COUNTIFS(J:J,"Digital",H:H,">=01/01/2026",H:H,"<=31/12/2026") -> 5 | V9: =COUNTIFS(H:H,">=01/01/2026",H:H,"<=31/12/2026") -> 11 | W9: =SUMIFS(K:K,H:H,">=01/01/2026",H:H,"<=31/12/2026") -> 2658 | X9: =W9/365 -> 7.2821918
A10: 19 | B10: Livro | C10: Um Coração Simples | D10: Gustave Flaubert | E10: Grua | F10: Luiz | G10: 46146 | H10: 46146 | I10: =IF(H10="", "", H10 - G10 + 1) -> 1 | J10: Físico | K10: 80 | L10: 3.5 | M10: 3.5 | N10: =ROUND(AVERAGE(L10:M10)*2,0)/2 -> 3.5
A11: 18 | B11: Livro | C11: Romeu e Julieta | D11: William Shakespeare | E11: Antofágica | F11: Diana | G11: 46120 | H11: 46130 | I11: =IF(H11="", "", H11 - G11 + 1) -> 11 | J11: Físico | K11: 240 | L11: 3.5 | M11: 3 | N11: =ROUND(AVERAGE(L11:M11)*2,0)/2 -> 3.5 | P11: Quantia | Q11: Livros | R11: HQs | S11: Mangás | T11: Físico | U11: Digital | V11: Total | W11: Páginas | X11: Média / L
A12: 17 | B12: Livro | C12: Em seus passos o que faria Jesus? | D12: Charles M. Sheldon | E12: Mundo Cristão | F12: Diana | G12: 46084 | H12: 46094 | I12: =IF(H12="", "", H12 - G12 + 1) -> 11 | J12: Digital | K12: 251 | L12: 4 | M12: 4 | N12: =ROUND(AVERAGE(L12:M12)*2,0)/2 -> 4 | P12: Total | Q12: =SUM(Q7:Q9) -> 25 | R12: =SUM(R7:R9) -> 0 | S12: =SUM(S7:S9) -> 0 | T12: =SUM(T7:T9) -> 18 | U12: =SUM(U7:U9) -> 7 | V12: =SUM(V7:V9) -> 25 | W12: =SUM(W7:W9) -> 8518 | X12: =SUM(V12)/3 -> 8.3333333
A13: 16 | B13: Livro | C13: O cavaleiro inexistente | D13: Italo Calvino | E13: Companhia de Bolso | F13: Luiz | G13: 46076 | H13: 46081 | I13: =IF(H13="", "", H13 - G13 + 1) -> 6 | J13: Digital | K13: 119 | L13: 3 | M13: 3 | N13: =ROUND(AVERAGE(L13:M13)*2,0)/2 -> 3
A14: 15 | B14: Livro | C14: Convite para um homicídio | D14: Agatha Christie | E14: HarperCollins | F14: Luiz | G14: 46032 | H14: 46046 | I14: =IF(H14="", "", H14 - G14 + 1) -> 15 | J14: Físico | K14: 272 | L14: 4 | M14: 4 | N14: =ROUND(AVERAGE(L14:M14)*2,0)/2 -> 4 | P14: Mês | Q14: Total | S14: Nota | T14: Tipo | U14: Nº | W14: Indicação | X14: Nº
A15: 14 | B15: Livro | C15: Uma canção de natal | D15: Charles Dickens | E15: Sextante | F15: Diana | G15: 46013 | H15: 46019 | I15: =IF(H15="", "", H15 - G15 + 1) -> 7 | J15: Digital | K15: 156 | L15: 4 | M15: 4 | N15: =ROUND(AVERAGE(L15:M15)*2,0)/2 -> 4 | P15: Janeiro | Q15: =SUMPRODUCT((MONTH(H2:H745)=1)*(H2:H745<>"")) -> 1 | S15: 5 | T15: Perfeito | U15: =COUNTIF(N:N,5) -> 5 | W15: Diana | X15: =COUNTIF(F:F,"Diana") -> 17
A16: 13 | B16: Livro | C16: O homem mais feliz do mundo | D16: Eddie Jaku | E16: Intrínseca | F16: Luiz | G16: 45997 | H16: 46001 | I16: =IF(H16="", "", H16 - G16 + 1) -> 5 | J16: Digital | K16: 149 | L16: 4.5 | M16: 4.5 | N16: =ROUND(AVERAGE(L16:M16)*2,0)/2 -> 4.5 | P16: Fevereiro | Q16: =SUMPRODUCT(--(MONTH(H2:H745)=2)) -> 1 | S16: 4.5 | T16: Incrível | U16: =COUNTIF(N:N,4.5) -> 7 | W16: Luiz | X16: =COUNTIF(F:F,"Luiz") -> 8
A17: 12 | B17: Livro | C17: A Dama das Camélias | D17: Alexandre Dumas Filho | E17: Martin Claret | F17: Diana | G17: 45973 | H17: 45980 | I17: =IF(H17="", "", H17 - G17 + 1) -> 8 | J17: Físico | K17: 291 | L17: 5 | M17: 4 | N17: =ROUND(AVERAGE(L17:M17)*2,0)/2 -> 4.5 | P17: Março | Q17: =SUMPRODUCT(--(MONTH(H2:H745)=3)) -> 2 | S17: 4 | T17: Ótimo | U17: =COUNTIF(N:N,4) -> 8 | W17: Outro | X17: =COUNTA(F:F)-COUNTIF(F:F,"Diana")-COUNTIF(F:F,"Luiz")-1 -> 0
A18: 11 | B18: Livro | C18: Hora zero | D18: Agatha Christie | E18: HarperCollins | F18: Diana | G18: 45932 | H18: 45944 | I18: =IF(H18="", "", H18 - G18 + 1) -> 13 | J18: Físico | K18: 224 | L18: 4 | M18: 4 | N18: =ROUND(AVERAGE(L18:M18)*2,0)/2 -> 4 | P18: Abril | Q18: =SUMPRODUCT(--(MONTH(H2:H745)=4)) -> 2 | S18: 3.5 | T18: Bom | U18: =COUNTIF(N:N,3.5) -> 3 | W18: Total | X18: =SUM(X15:X17) -> 25
A19: 10 | B19: Livro | C19: Cem anos de solidão | D19: Gabriel García Márquez | E19: Record | F19: Diana | G19: 45889 | H19: 45929 | I19: =IF(H19="", "", H19 - G19 + 1) -> 41 | J19: Físico | K19: 432 | L19: 2.5 | M19: 2.5 | N19: =ROUND(AVERAGE(L19:M19)*2,0)/2 -> 2.5 | P19: Maio | Q19: =SUMPRODUCT(--(MONTH(H2:H745)=5)) -> 2 | S19: 3 | T19: Decente | U19: =COUNTIF(N:N,3) -> 1
A20: 9 | B20: Livro | C20: Os três mosqueteiros | D20: Alexandre Dumas | E20: Zahar | F20: Diana | G20: 45784 | H20: 45836 | I20: =IF(H20="", "", H20 - G20 + 1) -> 53 | J20: Físico | K20: 792 | L20: 5 | M20: 5 | N20: =ROUND(AVERAGE(L20:M20)*2,0)/2 -> 5 | P20: Junho | Q20: =SUMPRODUCT(--(MONTH(H2:H745)=6)) -> 4 | S20: 2.5 | T20: Fraco | U20: =COUNTIF(N:N,2.5) -> 1
A21: 8 | B21: Livro | C21: O Assassinato de Roger Ackroyd | D21: Agatha Christie | E21: Globo Livros | F21: Diana | G21: 45778 | H21: 45783 | I21: =IF(H21="", "", H21 - G21 + 1) -> 6 | J21: Físico | K21: 312 | L21: 4.5 | M21: 5 | N21: =ROUND(AVERAGE(L21:M21)*2,0)/2 -> 5 | P21: Julho | Q21: =SUMPRODUCT(--(MONTH(H2:H745)=7)) -> 0 | S21: 2 | T21: Ruim | U21: =COUNTIF(N:N,2) -> 0
A22: 7 | B22: Livro | C22: Pachinko | D22: Min Jin Lee | E22: Intrínseca | F22: Luiz | G22: 45759 | H22: 45773 | I22: =IF(H22="", "", H22 - G22 + 1) -> 15 | J22: Físico | K22: 528 | L22: 5 | M22: 5 | N22: =ROUND(AVERAGE(L22:M22)*2,0)/2 -> 5 | P22: Agosto | Q22: =SUMPRODUCT(--(MONTH(H2:H745)=8)) -> 1 | S22: 1.5 | T22: Péssimo | U22: =COUNTIF(N:N,1.5) -> 0
A23: 6 | B23: Livro | C23: O Conde de Monte Cristo | D23: Alexandre Dumas | E23: Martin Claret | F23: Diana | G23: 45661 | H23: 45747 | I23: =IF(H23="", "", H23 - G23 + 1) -> 87 | J23: Físico | K23: 1304 | L23: 5 | M23: 5 | N23: =ROUND(AVERAGE(L23:M23)*2,0)/2 -> 5 | P23: Setembro | Q23: =SUMPRODUCT(--(MONTH(H2:H745)=9)) -> 3 | S23: 1 | T23: Horrível | U23: =COUNTIF(N:N,1) -> 0
A24: 5 | B24: Livro | C24: O Natal de Hercule Poirot | D24: Agatha Christie | E24: HarperCollins | F24: Diana | G24: 45648 | H24: 45653 | I24: =IF(H24="", "", H24 - G24 + 1) -> 6 | J24: Físico | K24: 224 | L24: 4.5 | M24: 4.5 | N24: =ROUND(AVERAGE(L24:M24)*2,0)/2 -> 4.5 | P24: Outubro | Q24: =SUMPRODUCT(--(MONTH(H2:H745)=10)) -> 2 | S24: - | T24: Total | U24: =SUM(U15:U23) -> 25
A25: 4 | B25: Livro | C25: Guerra, Adorável Guerra | D25: Julie Berry | E25: Darkside | F25: Luiz | G25: 45625 | H25: 45639 | I25: =IF(H25="", "", H25 - G25 + 1) -> 15 | J25: Físico | K25: 448 | L25: 4 | M25: 4 | N25: =ROUND(AVERAGE(L25:M25)*2,0)/2 -> 4 | P25: Novembro | Q25: =SUMPRODUCT(--(MONTH(H2:H745)=11)) -> 3
A26: 3 | B26: Livro | C26: Os Bons Companheiros | D26: Nicholas Pileggi | E26: Darkside | F26: Luiz | G26: 45600 | H26: 45613 | I26: =IF(H26="", "", H26 - G26 + 1) -> 14 | J26: Físico | K26: 272 | L26: 4 | M26: 5 | N26: =ROUND(AVERAGE(L26:M26)*2,0)/2 -> 4.5 | P26: Dezembro | Q26: =SUMPRODUCT(--(MONTH(H2:H745)=12)) -> 4
A27: 2 | B27: Livro | C27: O Poderoso Chefão | D27: Mario Puzo | E27: Record | F27: Luiz | G27: 45563 | H27: 45598 | I27: =IF(H27="", "", H27 - G27 + 1) -> 36 | J27: Físico | K27: 496 | L27: 5 | M27: 5 | N27: =ROUND(AVERAGE(L27:M27)*2,0)/2 -> 5 | P27: Total | Q27: =SUM(Q15:Q26) -> 25
A28: 1 | B28: Livro | C28: A Noite das Bruxas | D28: Agatha Christie | E28: L&PM | F28: Diana | G28: 45512 | H28: 45534 | I28: =IF(H28="", "", H28 - G28 + 1) -> 23 | J28: Físico | K28: 232 | L28: 3.5 | M28: 3.5 | N28: =ROUND(AVERAGE(L28:M28)*2,0)/2 -> 3.5

Sheet Leitura Ano Mês
C3: 2011 | D3: Nº | E3: 2012 | F3: Nº | G3: 2013 | H3: Nº | I3: 2014 | J3: Nº | K3: 2015 | L3: Nº | M3: 2016 | N3: Nº | O3: 2017 | P3: Nº | Q3: 2018 | R3: Nº | S3: 2019 | T3: Nº | U3: 2020 | V3: Nº | X3: Média mês | Y3: Nº
C4: Janeiro | D4: =COUNTIFS('Livros Finalizados'!$I:$I,">=01/01/2011",'Livros Finalizados'!$I:$I,"<=31/01/2011") -> 0 | E4: Janeiro | F4: =COUNTIFS('Livros Finalizados'!$I:$I,">=01/01/2012",'Livros Finalizados'!$I:$I,"<=31/01/2012") -> 0 | G4: Janeiro | H4: =COUNTIFS('Livros Finalizados'!$I:$I,">=01/01/2013",'Livros Finalizados'!$I:$I,"<=31/01/2013") -> 0 | I4: Janeiro | J4: =COUNTIFS('Livros Finalizados'!$I:$I,">=01/01/2014",'Livros Finalizados'!$I:$I,"<=31/01/2014") -> 0 | K4: Janeiro | L4: =COUNTIFS('Livros Finalizados'!$I:$I,">=01/01/2015",'Livros Finalizados'!$I:$I,"<=31/01/2015") -> 1 | M4: Janeiro | N4: =COUNTIFS('Livros Finalizados'!$I:$I,">=01/01/2016",'Livros Finalizados'!$I:$I,"<=31/01/2016") -> 0 | O4: Janeiro | P4: =COUNTIFS('Livros Finalizados'!$I:$I,">=01/01/2017",'Livros Finalizados'!$I:$I,"<=31/01/2017") -> 1 | Q4: Janeiro | R4: =COUNTIFS('Livros Finalizados'!$I:$I,">=01/01/2018",'Livros Finalizados'!$I:$I,"<=31/01/2018") -> 0 | S4: Janeiro | T4: =COUNTIFS('Livros Finalizados'!$I:$I,">=01/01/2019",'Livros Finalizados'!$I:$I,"<=31/01/2019") -> 0 | U4: Janeiro | V4: =COUNTIFS('Livros Finalizados'!$I:$I,">=01/01/2020",'Livros Finalizados'!$I:$I,"<=31/01/2020") -> 0 | X4: Janeiro | Y4: =AVERAGE(D4,F4,H4,J4,L4,N4,P4,R4,T4,V4,D19,F19,H19,J19,L19,N19) -> 0.6875
C5: Fevereiro | D5: =COUNTIFS('Livros Finalizados'!$I:$I,">=01/02/2011",'Livros Finalizados'!$I:$I,"<=28/02/2011") -> 0 | E5: Fevereiro | F5: =COUNTIFS('Livros Finalizados'!$I:$I,">=01/02/2012",'Livros Finalizados'!$I:$I,"<=29/02/2012") -> 0 | G5: Fevereiro | H5: =COUNTIFS('Livros Finalizados'!$I:$I,">=01/03/2013",'Livros Finalizados'!$I:$I,"<=28/02/2013") -> 0 | I5: Fevereiro | J5: =COUNTIFS('Livros Finalizados'!$I:$I,">=01/02/2014",'Livros Finalizados'!$I:$I,"<=28/02/2014") -> 1 | K5: Fevereiro | L5: =COUNTIFS('Livros Finalizados'!$I:$I,">=01/02/2015",'Livros Finalizados'!$I:$I,"<=28/02/2015") -> 0 | M5: Fevereiro | N5: =COUNTIFS('Livros Finalizados'!$I:$I,">=01/02/2016",'Livros Finalizados'!$I:$I,"<=29/02/2016") -> 0 | O5: Fevereiro | P5: =COUNTIFS('Livros Finalizados'!$I:$I,">=01/02/2017",'Livros Finalizados'!$I:$I,"<=28/02/2017") -> 0 | Q5: Fevereiro | R5: =COUNTIFS('Livros Finalizados'!$I:$I,">=01/02/2018",'Livros Finalizados'!$I:$I,"<=28/02/2018") -> 0 | S5: Fevereiro | T5: =COUNTIFS('Livros Finalizados'!$I:$I,">=01/02/2019",'Livros Finalizados'!$I:$I,"<=28/02/2019") -> 0 | U5: Fevereiro | V5: =COUNTIFS('Livros Finalizados'!$I:$I,">=01/02/2020",'Livros Finalizados'!$I:$I,"<=29/02/2020") -> 0 | X5: Fevereiro | Y5: =AVERAGE(D5,F5,H5,J5,L5,N5,P5,R5,T5,V5,D20,F20,H20,J20,L20,N20) -> 0.5
C6: Março | D6: =COUNTIFS('Livros Finalizados'!$I:$I,">=01/03/2011",'Livros Finalizados'!$I:$I,"<=31/03/2011") -> 0 | E6: Março | F6: =COUNTIFS('Livros Finalizados'!$I:$I,">=01/03/2012",'Livros Finalizados'!$I:$I,"<=31/03/2012") -> 0 | G6: Março | H6: =COUNTIFS('Livros Finalizados'!$I:$I,">=01/03/2013",'Livros Finalizados'!$I:$I,"<=31/03/2013") -> 0 | I6: Março | J6: =COUNTIFS('Livros Finalizados'!$I:$I,">=01/03/2014",'Livros Finalizados'!$I:$I,"<=31/03/2014") -> 0 | K6: Março | L6: =COUNTIFS('Livros Finalizados'!$I:$I,">=01/03/2015",'Livros Finalizados'!$I:$I,"<=31/03/2015") -> 0 | M6: Março | N6: =COUNTIFS('Livros Finalizados'!$I:$I,">=01/03/2016",'Livros Finalizados'!$I:$I,"<=31/03/2016") -> 0 | O6: Março | P6: =COUNTIFS('Livros Finalizados'!$I:$I,">=01/03/2017",'Livros Finalizados'!$I:$I,"<=31/03/2017") -> 0 | Q6: Março | R6: =COUNTIFS('Livros Finalizados'!$I:$I,">=01/03/2018",'Livros Finalizados'!$I:$I,"<=31/03/2018") -> 0 | S6: Março | T6: =COUNTIFS('Livros Finalizados'!$I:$I,">=01/03/2019",'Livros Finalizados'!$I:$I,"<=31/03/2019") -> 0 | U6: Março | V6: =COUNTIFS('Livros Finalizados'!$I:$I,">=01/03/2020",'Livros Finalizados'!$I:$I,"<=31/03/2020") -> 0 | X6: Março | Y6: =AVERAGE(D6,F6,H6,J6,L6,N6,P6,R6,T6,V6,D21,F21,H21,J21,L21,N21) -> 0.625
C7: Abril | D7: =COUNTIFS('Livros Finalizados'!$I:$I,">=01/04/2011",'Livros Finalizados'!$I:$I,"<=30/04/2011") -> 0 | E7: Abril | F7: =COUNTIFS('Livros Finalizados'!$I:$I,">=01/04/2012",'Livros Finalizados'!$I:$I,"<=30/04/2012") -> 0 | G7: Abril | H7: =COUNTIFS('Livros Finalizados'!$I:$I,">=01/04/2013",'Livros Finalizados'!$I:$I,"<=30/04/2013") -> 0 | I7: Abril | J7: =COUNTIFS('Livros Finalizados'!$I:$I,">=01/04/2014",'Livros Finalizados'!$I:$I,"<=30/04/2014") -> 0 | K7: Abril | L7: =COUNTIFS('Livros Finalizados'!$I:$I,">=01/04/2015",'Livros Finalizados'!$I:$I,"<=30/04/2015") -> 0 | M7: Abril | N7: =COUNTIFS('Livros Finalizados'!$I:$I,">=01/04/2016",'Livros Finalizados'!$I:$I,"<=30/04/2016") -> 0 | O7: Abril | P7: =COUNTIFS('Livros Finalizados'!$I:$I,">=01/04/2017",'Livros Finalizados'!$I:$I,"<=30/04/2017") -> 1 | Q7: Abril | R7: =COUNTIFS('Livros Finalizados'!$I:$I,">=01/04/2018",'Livros Finalizados'!$I:$I,"<=30/04/2018") -> 0 | S7: Abril | T7: =COUNTIFS('Livros Finalizados'!$I:$I,">=01/04/2019",'Livros Finalizados'!$I:$I,"<=30/04/2019") -> 0 | U7: Abril | V7: =COUNTIFS('Livros Finalizados'!$I:$I,">=01/04/2020",'Livros Finalizados'!$I:$I,"<=30/04/2020") -> 0 | X7: Abril | Y7: =AVERAGE(D7,F7,H7,J7,L7,N7,P7,R7,T7,V7,D22,F22,H22,J22,L22,N22) -> 0.5625
C8: Maio | D8: =COUNTIFS('Livros Finalizados'!$I:$I,">=01/05/2011",'Livros Finalizados'!$I:$I,"<=31/05/2011") -> 0 | E8: Maio | F8: =COUNTIFS('Livros Finalizados'!$I:$I,">=01/05/2012",'Livros Finalizados'!$I:$I,"<=31/05/2012") -> 0 | G8: Maio | H8: =COUNTIFS('Livros Finalizados'!$I:$I,">=01/05/2013",'Livros Finalizados'!$I:$I,"<=31/05/2013") -> 0 | I8: Maio | J8: =COUNTIFS('Livros Finalizados'!$I:$I,">=01/05/2014",'Livros Finalizados'!$I:$I,"<=31/05/2014") -> 7 | K8: Maio | L8: =COUNTIFS('Livros Finalizados'!$I:$I,">=01/05/2015",'Livros Finalizados'!$I:$I,"<=31/05/2015") -> 0 | M8: Maio | N8: =COUNTIFS('Livros Finalizados'!$I:$I,">=01/05/2016",'Livros Finalizados'!$I:$I,"<=31/05/2016") -> 0 | O8: Maio | P8: =COUNTIFS('Livros Finalizados'!$I:$I,">=01/05/2017",'Livros Finalizados'!$I:$I,"<=31/05/2017") -> 2 | Q8: Maio | R8: =COUNTIFS('Livros Finalizados'!$I:$I,">=01/05/2018",'Livros Finalizados'!$I:$I,"<=31/05/2018") -> 0 | S8: Maio | T8: =COUNTIFS('Livros Finalizados'!$I:$I,">=01/05/2019",'Livros Finalizados'!$I:$I,"<=31/05/2019") -> 0 | U8: Maio | V8: =COUNTIFS('Livros Finalizados'!$I:$I,">=01/05/2020",'Livros Finalizados'!$I:$I,"<=31/05/2020") -> 0 | X8: Maio | Y8: =AVERAGE(D8,F8,H8,J8,L8,N8,P8,R8,T8,V8,D23,F23,H23,J23,L23,N23) -> 1.375
C9: Junho | D9: =COUNTIFS('Livros Finalizados'!$I:$I,">=01/06/2011",'Livros Finalizados'!$I:$I,"<=30/06/2011") -> 0 | E9: Junho | F9: =COUNTIFS('Livros Finalizados'!$I:$I,">=01/06/2012",'Livros Finalizados'!$I:$I,"<=30/06/2012") -> 1 | G9: Junho | H9: =COUNTIFS('Livros Finalizados'!$I:$I,">=01/06/2013",'Livros Finalizados'!$I:$I,"<=30/06/2013") -> 0 | I9: Junho | J9: =COUNTIFS('Livros Finalizados'!$I:$I,">=01/06/2014",'Livros Finalizados'!$I:$I,"<=30/06/2014") -> 3 | K9: Junho | L9: =COUNTIFS('Livros Finalizados'!$I:$I,">=01/06/2015",'Livros Finalizados'!$I:$I,"<=30/06/2015") -> 1 | M9: Junho | N9: =COUNTIFS('Livros Finalizados'!$I:$I,">=01/06/2016",'Livros Finalizados'!$I:$I,"<=30/06/2016") -> 2 | O9: Junho | P9: =COUNTIFS('Livros Finalizados'!$I:$I,">=01/06/2017",'Livros Finalizados'!$I:$I,"<=30/06/2017") -> 0 | Q9: Junho | R9: =COUNTIFS('Livros Finalizados'!$I:$I,">=01/06/2018",'Livros Finalizados'!$I:$I,"<=30/06/2018") -> 0 | S9: Junho | T9: =COUNTIFS('Livros Finalizados'!$I:$I,">=01/06/2019",'Livros Finalizados'!$I:$I,"<=30/06/2019") -> 0 | U9: Junho | V9: =COUNTIFS('Livros Finalizados'!$I:$I,">=01/06/2020",'Livros Finalizados'!$I:$I,"<=30/06/2020") -> 0 | X9: Junho | Y9: =AVERAGE(D9,F9,H9,J9,L9,N9,P9,R9,T9,V9,D24,F24,H24,J24,L24,N24) -> 1.9375
C10: Julho | D10: =COUNTIFS('Livros Finalizados'!$I:$I,">=01/07/2011",'Livros Finalizados'!$I:$I,"<=31/07/2011") -> 0 | E10: Julho | F10: =COUNTIFS('Livros Finalizados'!$I:$I,">=01/07/2012",'Livros Finalizados'!$I:$I,"<=31/07/2012") -> 0 | G10: Julho | H10: =COUNTIFS('Livros Finalizados'!$I:$I,">=01/07/2013",'Livros Finalizados'!$I:$I,"<=31/07/2013") -> 0 | I10: Julho | J10: =COUNTIFS('Livros Finalizados'!$I:$I,">=01/07/2014",'Livros Finalizados'!$I:$I,"<=31/07/2014") -> 3 | K10: Julho | L10: =COUNTIFS('Livros Finalizados'!$I:$I,">=01/07/2015",'Livros Finalizados'!$I:$I,"<=31/07/2015") -> 0 | M10: Julho | N10: =COUNTIFS('Livros Finalizados'!$I:$I,">=01/07/2016",'Livros Finalizados'!$I:$I,"<=31/07/2016") -> 2 | O10: Julho | P10: =COUNTIFS('Livros Finalizados'!$I:$I,">=01/07/2017",'Livros Finalizados'!$I:$I,"<=31/07/2017") -> 0 | Q10: Julho | R10: =COUNTIFS('Livros Finalizados'!$I:$I,">=01/07/2018",'Livros Finalizados'!$I:$I,"<=31/07/2018") -> 0 | S10: Julho | T10: =COUNTIFS('Livros Finalizados'!$I:$I,">=01/07/2019",'Livros Finalizados'!$I:$I,"<=31/07/2019") -> 0 | U10: Julho | V10: =COUNTIFS('Livros Finalizados'!$I:$I,">=01/07/2020",'Livros Finalizados'!$I:$I,"<=31/07/2020") -> 0 | X10: Julho | Y10: =AVERAGE(D10,F10,H10,J10,L10,N10,P10,R10,T10,V10,D25,F25,H25,J25,L25,N25) -> 1.4375
C11: Agosto | D11: =COUNTIFS('Livros Finalizados'!$I:$I,">=01/08/2011",'Livros Finalizados'!$I:$I,"<=31/08/2011") -> 0 | E11: Agosto | F11: =COUNTIFS('Livros Finalizados'!$I:$I,">=01/08/2012",'Livros Finalizados'!$I:$I,"<=31/08/2012") -> 1 | G11: Agosto | H11: =COUNTIFS('Livros Finalizados'!$I:$I,">=01/08/2013",'Livros Finalizados'!$I:$I,"<=31/08/2013") -> 1 | I11: Agosto | J11: =COUNTIFS('Livros Finalizados'!$I:$I,">=01/08/2014",'Livros Finalizados'!$I:$I,"<=31/08/2014") -> 1 | K11: Agosto | L11: =COUNTIFS('Livros Finalizados'!$I:$I,">=01/08/2015",'Livros Finalizados'!$I:$I,"<=31/08/2015") -> 0 | M11: Agosto | N11: =COUNTIFS('Livros Finalizados'!$I:$I,">=01/08/2016",'Livros Finalizados'!$I:$I,"<=31/08/2016") -> 1 | O11: Agosto | P11: =COUNTIFS('Livros Finalizados'!$I:$I,">=01/08/2017",'Livros Finalizados'!$I:$I,"<=31/08/2017") -> 0 | Q11: Agosto | R11: =COUNTIFS('Livros Finalizados'!$I:$I,">=01/08/2018",'Livros Finalizados'!$I:$I,"<=31/08/2018") -> 0 | S11: Agosto | T11: =COUNTIFS('Livros Finalizados'!$I:$I,">=01/08/2019",'Livros Finalizados'!$I:$I,"<=31/08/2019") -> 1 | U11: Agosto | V11: =COUNTIFS('Livros Finalizados'!$I:$I,">=01/08/2020",'Livros Finalizados'!$I:$I,"<=31/08/2020") -> 0 | X11: Agosto | Y11: =AVERAGE(D11,F11,H11,J11,L11,N11,P11,R11,T11,V11,D26,F26,H26,J26,L26,N26) -> 0.875
C12: Setembro | D12: =COUNTIFS('Livros Finalizados'!$I:$I,">=01/09/2011",'Livros Finalizados'!$I:$I,"<=30/09/2011") -> 1 | E12: Setembro | F12: =COUNTIFS('Livros Finalizados'!$I:$I,">=01/09/2012",'Livros Finalizados'!$I:$I,"<=30/09/2012") -> 0 | G12: Setembro | H12: =COUNTIFS('Livros Finalizados'!$I:$I,">=01/09/2013",'Livros Finalizados'!$I:$I,"<=30/09/2013") -> 1 | I12: Setembro | J12: =COUNTIFS('Livros Finalizados'!$I:$I,">=01/09/2014",'Livros Finalizados'!$I:$I,"<=30/09/2014") -> 0 | K12: Setembro | L12: =COUNTIFS('Livros Finalizados'!$I:$I,">=01/09/2015",'Livros Finalizados'!$I:$I,"<=30/09/2015") -> 0 | M12: Setembro | N12: =COUNTIFS('Livros Finalizados'!$I:$I,">=01/09/2016",'Livros Finalizados'!$I:$I,"<=30/09/2016") -> 2 | O12: Setembro | P12: =COUNTIFS('Livros Finalizados'!$I:$I,">=01/09/2017",'Livros Finalizados'!$I:$I,"<=30/09/2017") -> 0 | Q12: Setembro | R12: =COUNTIFS('Livros Finalizados'!$I:$I,">=01/09/2018",'Livros Finalizados'!$I:$I,"<=30/09/2018") -> 0 | S12: Setembro | T12: =COUNTIFS('Livros Finalizados'!$I:$I,">=01/09/2019",'Livros Finalizados'!$I:$I,"<=30/09/2019") -> 2 | U12: Setembro | V12: =COUNTIFS('Livros Finalizados'!$I:$I,">=01/09/2020",'Livros Finalizados'!$I:$I,"<=30/09/2020") -> 0 | X12: Setembro | Y12: =AVERAGE(D12,F12,H12,J12,L12,N12,P12,R12,T12,V12,D27,F27,H27,J27,L27,N27) -> 0.875
C13: Outubro | D13: =COUNTIFS('Livros Finalizados'!$I:$I,">=01/10/2011",'Livros Finalizados'!$I:$I,"<=31/10/2011") -> 0 | E13: Outubro | F13: =COUNTIFS('Livros Finalizados'!$I:$I,">=01/10/2012",'Livros Finalizados'!$I:$I,"<=31/10/2012") -> 0 | G13: Outubro | H13: =COUNTIFS('Livros Finalizados'!$I:$I,">=01/10/2013",'Livros Finalizados'!$I:$I,"<=31/10/2013") -> 0 | I13: Outubro | J13: =COUNTIFS('Livros Finalizados'!$I:$I,">=01/10/2014",'Livros Finalizados'!$I:$I,"<=31/10/2014") -> 0 | K13: Outubro | L13: =COUNTIFS('Livros Finalizados'!$I:$I,">=01/10/2015",'Livros Finalizados'!$I:$I,"<=31/10/2015") -> 0 | M13: Outubro | N13: =COUNTIFS('Livros Finalizados'!$I:$I,">=01/10/2016",'Livros Finalizados'!$I:$I,"<=31/10/2016") -> 1 | O13: Outubro | P13: =COUNTIFS('Livros Finalizados'!$I:$I,">=01/10/2017",'Livros Finalizados'!$I:$I,"<=31/10/2017") -> 0 | Q13: Outubro | R13: =COUNTIFS('Livros Finalizados'!$I:$I,">=01/10/2018",'Livros Finalizados'!$I:$I,"<=31/10/2018") -> 0 | S13: Outubro | T13: =COUNTIFS('Livros Finalizados'!$I:$I,">=01/10/2019",'Livros Finalizados'!$I:$I,"<=31/10/2019") -> 2 | U13: Outubro | V13: =COUNTIFS('Livros Finalizados'!$I:$I,">=01/10/2020",'Livros Finalizados'!$I:$I,"<=31/10/2020") -> 0 | X13: Outubro | Y13: =AVERAGE(D13,F13,H13,J13,L13,N13,P13,R13,T13,V13,D28,F28,H28,J28,L28,N28) -> 0.6875
C14: Novembro | D14: =COUNTIFS('Livros Finalizados'!$I:$I,">=01/11/2011",'Livros Finalizados'!$I:$I,"<=30/11/2011") -> 0 | E14: Novembro | F14: =COUNTIFS('Livros Finalizados'!$I:$I,">=01/11/2012",'Livros Finalizados'!$I:$I,"<=30/11/2012") -> 0 | G14: Novembro | H14: =COUNTIFS('Livros Finalizados'!$I:$I,">=01/11/2013",'Livros Finalizados'!$I:$I,"<=30/11/2013") -> 1 | I14: Novembro | J14: =COUNTIFS('Livros Finalizados'!$I:$I,">=01/11/2014",'Livros Finalizados'!$I:$I,"<=30/11/2014") -> 0 | K14: Novembro | L14: =COUNTIFS('Livros Finalizados'!$I:$I,">=01/11/2015",'Livros Finalizados'!$I:$I,"<=30/11/2015") -> 0 | M14: Novembro | N14: =COUNTIFS('Livros Finalizados'!$I:$I,">=01/11/2016",'Livros Finalizados'!$I:$I,"<=30/11/2016") -> 2 | O14: Novembro | P14: =COUNTIFS('Livros Finalizados'!$I:$I,">=01/11/2017",'Livros Finalizados'!$I:$I,"<=30/11/2017") -> 0 | Q14: Novembro | R14: =COUNTIFS('Livros Finalizados'!$I:$I,">=01/11/2018",'Livros Finalizados'!$I:$I,"<=30/11/2018") -> 0 | S14: Novembro | T14: =COUNTIFS('Livros Finalizados'!$I:$I,">=01/11/2019",'Livros Finalizados'!$I:$I,"<=30/11/2019") -> 2 | U14: Novembro | V14: =COUNTIFS('Livros Finalizados'!$I:$I,">=01/11/2020",'Livros Finalizados'!$I:$I,"<=30/11/2020") -> 0 | X14: Novembro | Y14: =AVERAGE(D14,F14,H14,J14,L14,N14,P14,R14,T14,V14,D29,F29,H29,J29,L29,N29) -> 1.1875
C15: Dezembro | D15: =COUNTIFS('Livros Finalizados'!$I:$I,">=01/12/2011",'Livros Finalizados'!$I:$I,"<=31/12/2011") -> 1 | E15: Dezembro | F15: =COUNTIFS('Livros Finalizados'!$I:$I,">=01/12/2012",'Livros Finalizados'!$I:$I,"<=31/12/2012") -> 0 | G15: Dezembro | H15: =COUNTIFS('Livros Finalizados'!$I:$I,">=01/12/2013",'Livros Finalizados'!$I:$I,"<=31/12/2013") -> 0 | I15: Dezembro | J15: =COUNTIFS('Livros Finalizados'!$I:$I,">=01/12/2014",'Livros Finalizados'!$I:$I,"<=31/12/2014") -> 0 | K15: Dezembro | L15: =COUNTIFS('Livros Finalizados'!$I:$I,">=01/12/2015",'Livros Finalizados'!$I:$I,"<=31/12/2015") -> 0 | M15: Dezembro | N15: =COUNTIFS('Livros Finalizados'!$I:$I,">=01/12/2016",'Livros Finalizados'!$I:$I,"<=31/12/2016") -> 0 | O15: Dezembro | P15: =COUNTIFS('Livros Finalizados'!$I:$I,">=01/12/2017",'Livros Finalizados'!$I:$I,"<=31/12/2017") -> 0 | Q15: Dezembro | R15: =COUNTIFS('Livros Finalizados'!$I:$I,">=01/12/2018",'Livros Finalizados'!$I:$I,"<=31/12/2018") -> 0 | S15: Dezembro | T15: =COUNTIFS('Livros Finalizados'!$I:$I,">=01/12/2019",'Livros Finalizados'!$I:$I,"<=31/12/2019") -> 0 | U15: Dezembro | V15: =COUNTIFS('Livros Finalizados'!$I:$I,">=01/12/2020",'Livros Finalizados'!$I:$I,"<=31/12/2020") -> 0 | X15: Dezembro | Y15: =AVERAGE(D15,F15,H15,J15,L15,N15,P15,R15,T15,V15,D30,F30,H30,J30,L30,N30) -> 1
C16: Total | D16: =SUM(D4:D15) -> 2 | E16: Total | F16: =SUM(F4:F15) -> 2 | G16: Janeiro | H16: =SUM(H4:H15) -> 3 | I16: Total | J16: =SUM(J4:J15) -> 15 | K16: Total | L16: =SUM(L4:L15) -> 2 | M16: Total | N16: =SUM(N4:N15) -> 10 | O16: Total | P16: =SUM(P4:P15) -> 4 | Q16: Total | R16: =SUM(R4:R15) -> 0 | S16: Total | T16: =SUM(T4:T15) -> 7 | U16: Total | V16: =SUM(V4:V15) -> 0 | X16: Total | Y16: =AVERAGE(Y4:Y15) -> 0.97916667
C18: 2021 | D18: Nº | E18: 2022 | F18: Nº | G18: 2023 | H18: Nº | I18: 2024 | J18: Nº | K18: 2025 | L18: Nº | M18: 2026 | N18: Nº | O18: 2027 | P18: Nº | Q18: 2028 | R18: Nº | S18: 2029 | T18: Nº | U18: 2030 | V18: Nº | X18: Total | Y18: =SUM(D16,F16,H16,J16,L16,N16,P16,R16,T16,V16,D31,F31,H31,J31,L31,N31,P31) -> 188
C19: Janeiro | D19: =COUNTIFS('Livros Finalizados'!$I:$I,">=01/01/2021",'Livros Finalizados'!$I:$I,"<=31/01/2021") -> 0 | E19: Janeiro | F19: =COUNTIFS('Livros Finalizados'!$I:$I,">=01/01/2022",'Livros Finalizados'!$I:$I,"<=31/01/2022") -> 4 | G19: Janeiro | H19: =COUNTIFS('Livros Finalizados'!$I:$I,">=01/01/2023",'Livros Finalizados'!$I:$I,"<=31/01/2023") -> 0 | I19: Janeiro | J19: =COUNTIFS('Livros Finalizados'!$I:$I,">=01/01/2024",'Livros Finalizados'!$I:$I,"<=31/01/2024") -> 1 | K19: Janeiro | L19: =COUNTIFS('Livros Finalizados'!$I:$I,">=01/01/2025",'Livros Finalizados'!$I:$I,"<=31/01/2025") -> 2 | M19: Janeiro | N19: =COUNTIFS('Livros Finalizados'!$I:$I,">=01/01/2026",'Livros Finalizados'!$I:$I,"<=31/01/2026") -> 2 | O19: Janeiro | P19: =COUNTIFS('Livros Finalizados'!$I:$I,">=01/01/2027",'Livros Finalizados'!$I:$I,"<=31/01/2027") -> 0 | Q19: Janeiro | S19: Janeiro | U19: Janeiro | V19: 0
C20: Fevereiro | D20: =COUNTIFS('Livros Finalizados'!$I:$I,">=01/02/2021",'Livros Finalizados'!$I:$I,"<=28/02/2021") -> 0 | E20: Fevereiro | F20: =COUNTIFS('Livros Finalizados'!$I:$I,">=01/02/2022",'Livros Finalizados'!$I:$I,"<=28/02/2022") -> 3 | G20: Fevereiro | H20: =COUNTIFS('Livros Finalizados'!$I:$I,">=01/02/2023",'Livros Finalizados'!$I:$I,"<=28/02/2023") -> 0 | I20: Fevereiro | J20: =COUNTIFS('Livros Finalizados'!$I:$I,">=01/02/2024",'Livros Finalizados'!$I:$I,"<=29/02/2024") -> 0 | K20: Fevereiro | L20: =COUNTIFS('Livros Finalizados'!$I:$I,">=01/02/2025",'Livros Finalizados'!$I:$I,"<=28/02/2025") -> 2 | M20: Fevereiro | N20: =COUNTIFS('Livros Finalizados'!$I:$I,">=01/02/2026",'Livros Finalizados'!$I:$I,"<=28/02/2026") -> 2 | O20: Fevereiro | P20: =COUNTIFS('Livros Finalizados'!$I:$I,">=01/02/2027",'Livros Finalizados'!$I:$I,"<=28/02/2027") -> 0 | Q20: Fevereiro | S20: Fevereiro | U20: Fevereiro | V20: 0
C21: Março | D21: =COUNTIFS('Livros Finalizados'!$I:$I,">=01/03/2021",'Livros Finalizados'!$I:$I,"<=31/03/2021") -> 0 | E21: Março | F21: =COUNTIFS('Livros Finalizados'!$I:$I,">=01/03/2022",'Livros Finalizados'!$I:$I,"<=31/03/2022") -> 0 | G21: Março | H21: =COUNTIFS('Livros Finalizados'!$I:$I,">=01/03/2023",'Livros Finalizados'!$I:$I,"<=31/03/2023") -> 0 | I21: Março | J21: =COUNTIFS('Livros Finalizados'!$I:$I,">=01/03/2024",'Livros Finalizados'!$I:$I,"<=31/03/2024") -> 4 | K21: Março | L21: =COUNTIFS('Livros Finalizados'!$I:$I,">=01/03/2025",'Livros Finalizados'!$I:$I,"<=31/03/2025") -> 4 | M21: Março | N21: =COUNTIFS('Livros Finalizados'!$I:$I,">=01/03/2026",'Livros Finalizados'!$I:$I,"<=31/03/2026") -> 2 | O21: Março | P21: =COUNTIFS('Livros Finalizados'!$I:$I,">=01/03/2027",'Livros Finalizados'!$I:$I,"<=31/03/2027") -> 0 | Q21: Março | S21: Março | U21: Março | V21: 0
C22: Abril | D22: =COUNTIFS('Livros Finalizados'!$I:$I,">=01/04/2021",'Livros Finalizados'!$I:$I,"<=30/04/2021") -> 0 | E22: Abril | F22: =COUNTIFS('Livros Finalizados'!$I:$I,">=01/04/2022",'Livros Finalizados'!$I:$I,"<=30/04/2022") -> 0 | G22: Abril | H22: =COUNTIFS('Livros Finalizados'!$I:$I,">=01/04/2023",'Livros Finalizados'!$I:$I,"<=30/04/2023") -> 0 | I22: Abril | J22: =COUNTIFS('Livros Finalizados'!$I:$I,">=01/04/2024",'Livros Finalizados'!$I:$I,"<=30/04/2024") -> 1 | K22: Abril | L22: =COUNTIFS('Livros Finalizados'!$I:$I,">=01/04/2025",'Livros Finalizados'!$I:$I,"<=30/04/2025") -> 3 | M22: Abril | N22: =COUNTIFS('Livros Finalizados'!$I:$I,">=01/04/2026",'Livros Finalizados'!$I:$I,"<=30/04/2026") -> 4 | O22: Abril | P22: =COUNTIFS('Livros Finalizados'!$I:$I,">=01/04/2027",'Livros Finalizados'!$I:$I,"<=30/04/2027") -> 0 | Q22: Abril | S22: Abril | U22: Abril | V22: 0
C23: Maio | D23: =COUNTIFS('Livros Finalizados'!$I:$I,">=01/05/2021",'Livros Finalizados'!$I:$I,"<=31/05/2021") -> 0 | E23: Maio | F23: =COUNTIFS('Livros Finalizados'!$I:$I,">=01/05/2022",'Livros Finalizados'!$I:$I,"<=31/05/2022") -> 0 | G23: Maio | H23: =COUNTIFS('Livros Finalizados'!$I:$I,">=01/05/2023",'Livros Finalizados'!$I:$I,"<=31/05/2023") -> 0 | I23: Maio | J23: =COUNTIFS('Livros Finalizados'!$I:$I,">=01/05/2024",'Livros Finalizados'!$I:$I,"<=31/05/2024") -> 9 | K23: Maio | L23: =COUNTIFS('Livros Finalizados'!$I:$I,">=01/05/2025",'Livros Finalizados'!$I:$I,"<=31/05/2025") -> 2 | M23: Maio | N23: =COUNTIFS('Livros Finalizados'!$I:$I,">=01/05/2026",'Livros Finalizados'!$I:$I,"<=31/05/2026") -> 2 | O23: Maio | P23: =COUNTIFS('Livros Finalizados'!$I:$I,">=01/05/2027",'Livros Finalizados'!$I:$I,"<=31/05/2027") -> 0 | Q23: Maio | S23: Maio | U23: Maio | V23: 0
C24: Junho | D24: =COUNTIFS('Livros Finalizados'!$I:$I,">=01/06/2021",'Livros Finalizados'!$I:$I,"<=30/06/2021") -> 0 | E24: Junho | F24: =COUNTIFS('Livros Finalizados'!$I:$I,">=01/06/2022",'Livros Finalizados'!$I:$I,"<=30/06/2022") -> 0 | G24: Junho | H24: =COUNTIFS('Livros Finalizados'!$I:$I,">=01/06/2023",'Livros Finalizados'!$I:$I,"<=30/06/2023") -> 0 | I24: Junho | J24: =COUNTIFS('Livros Finalizados'!$I:$I,">=01/06/2024",'Livros Finalizados'!$I:$I,"<=30/06/2024") -> 16 | K24: Junho | L24: =COUNTIFS('Livros Finalizados'!$I:$I,">=01/06/2025",'Livros Finalizados'!$I:$I,"<=30/06/2025") -> 4 | M24: Junho | N24: =COUNTIFS('Livros Finalizados'!$I:$I,">=01/06/2026",'Livros Finalizados'!$I:$I,"<=30/06/2026") -> 4 | O24: Junho | P24: =COUNTIFS('Livros Finalizados'!$I:$I,">=01/06/2027",'Livros Finalizados'!$I:$I,"<=30/06/2027") -> 0 | Q24: Junho | S24: Junho | U24: Junho | V24: 0
C25: Julho | D25: =COUNTIFS('Livros Finalizados'!$I:$I,">=01/07/2021",'Livros Finalizados'!$I:$I,"<=31/07/2021") -> 0 | E25: Julho | F25: =COUNTIFS('Livros Finalizados'!$I:$I,">=01/07/2022",'Livros Finalizados'!$I:$I,"<=31/07/2022") -> 0 | G25: Julho | H25: =COUNTIFS('Livros Finalizados'!$I:$I,">=01/07/2023",'Livros Finalizados'!$I:$I,"<=31/07/2023") -> 0 | I25: Julho | J25: =COUNTIFS('Livros Finalizados'!$I:$I,">=01/07/2024",'Livros Finalizados'!$I:$I,"<=31/07/2024") -> 9 | K25: Julho | L25: =COUNTIFS('Livros Finalizados'!$I:$I,">=01/07/2025",'Livros Finalizados'!$I:$I,"<=31/07/2025") -> 7 | M25: Julho | N25: =COUNTIFS('Livros Finalizados'!$I:$I,">=01/07/2026",'Livros Finalizados'!$I:$I,"<=31/07/2026") -> 2 | O25: Julho | P25: =COUNTIFS('Livros Finalizados'!$I:$I,">=01/07/2027",'Livros Finalizados'!$I:$I,"<=31/07/2027") -> 0 | Q25: Julho | S25: Julho | U25: Julho | V25: 0
C26: Agosto | D26: =COUNTIFS('Livros Finalizados'!$I:$I,">=01/08/2021",'Livros Finalizados'!$I:$I,"<=31/08/2021") -> 0 | E26: Agosto | F26: =COUNTIFS('Livros Finalizados'!$I:$I,">=01/08/2022",'Livros Finalizados'!$I:$I,"<=31/08/2022") -> 0 | G26: Agosto | H26: =COUNTIFS('Livros Finalizados'!$I:$I,">=01/08/2023",'Livros Finalizados'!$I:$I,"<=31/08/2023") -> 0 | I26: Agosto | J26: =COUNTIFS('Livros Finalizados'!$I:$I,">=01/08/2024",'Livros Finalizados'!$I:$I,"<=31/08/2024") -> 6 | K26: Agosto | L26: =COUNTIFS('Livros Finalizados'!$I:$I,">=01/08/2025",'Livros Finalizados'!$I:$I,"<=31/08/2025") -> 1 | M26: Agosto | N26: =COUNTIFS('Livros Finalizados'!$I:$I,">=01/08/2026",'Livros Finalizados'!$I:$I,"<=31/08/2026") -> 2 | O26: Agosto | P26: =COUNTIFS('Livros Finalizados'!$I:$I,">=01/08/2027",'Livros Finalizados'!$I:$I,"<=31/08/2027") -> 0 | Q26: Agosto | S26: Agosto | U26: Agosto | V26: 0
C27: Setembro | D27: =COUNTIFS('Livros Finalizados'!$I:$I,">=01/09/2021",'Livros Finalizados'!$I:$I,"<=30/09/2021") -> 0 | E27: Setembro | F27: =COUNTIFS('Livros Finalizados'!$I:$I,">=01/09/2022",'Livros Finalizados'!$I:$I,"<=30/09/2022") -> 0 | G27: Setembro | H27: =COUNTIFS('Livros Finalizados'!$I:$I,">=01/09/2023",'Livros Finalizados'!$I:$I,"<=30/09/2023") -> 0 | I27: Setembro | J27: =COUNTIFS('Livros Finalizados'!$I:$I,">=01/09/2024",'Livros Finalizados'!$I:$I,"<=30/09/2024") -> 3 | K27: Setembro | L27: =COUNTIFS('Livros Finalizados'!$I:$I,">=01/09/2025",'Livros Finalizados'!$I:$I,"<=30/09/2025") -> 1 | M27: Setembro | N27: =COUNTIFS('Livros Finalizados'!$I:$I,">=01/09/2026",'Livros Finalizados'!$I:$I,"<=30/09/2026") -> 4 | O27: Setembro | P27: =COUNTIFS('Livros Finalizados'!$I:$I,">=01/09/2027",'Livros Finalizados'!$I:$I,"<=30/09/2027") -> 0 | Q27: Setembro | S27: Setembro | U27: Setembro | V27: 0
C28: Outubro | D28: =COUNTIFS('Livros Finalizados'!$I:$I,">=01/10/2021",'Livros Finalizados'!$I:$I,"<=31/10/2021") -> 0 | E28: Outubro | F28: =COUNTIFS('Livros Finalizados'!$I:$I,">=01/10/2022",'Livros Finalizados'!$I:$I,"<=31/10/2022") -> 0 | G28: Outubro | H28: =COUNTIFS('Livros Finalizados'!$I:$I,">=01/10/2023",'Livros Finalizados'!$I:$I,"<=31/10/2023") -> 0 | I28: Outubro | J28: =COUNTIFS('Livros Finalizados'!$I:$I,">=01/10/2024",'Livros Finalizados'!$I:$I,"<=31/10/2024") -> 4 | K28: Outubro | L28: =COUNTIFS('Livros Finalizados'!$I:$I,">=01/10/2025",'Livros Finalizados'!$I:$I,"<=31/10/2025") -> 1 | M28: Outubro | N28: =COUNTIFS('Livros Finalizados'!$I:$I,">=01/10/2026",'Livros Finalizados'!$I:$I,"<=31/10/2026") -> 3 | O28: Outubro | P28: =COUNTIFS('Livros Finalizados'!$I:$I,">=01/10/2027",'Livros Finalizados'!$I:$I,"<=31/10/2027") -> 0 | Q28: Outubro | S28: Outubro | U28: Outubro | V28: 0
C29: Novembro | D29: =COUNTIFS('Livros Finalizados'!$I:$I,">=01/11/2021",'Livros Finalizados'!$I:$I,"<=30/11/2021") -> 1 | E29: Novembro | F29: =COUNTIFS('Livros Finalizados'!$I:$I,">=01/11/2022",'Livros Finalizados'!$I:$I,"<=30/11/2022") -> 0 | G29: Novembro | H29: =COUNTIFS('Livros Finalizados'!$I:$I,">=01/11/2023",'Livros Finalizados'!$I:$I,"<=30/11/2023") -> 0 | I29: Novembro | J29: =COUNTIFS('Livros Finalizados'!$I:$I,">=01/11/2024",'Livros Finalizados'!$I:$I,"<=30/11/2024") -> 10 | K29: Novembro | L29: =COUNTIFS('Livros Finalizados'!$I:$I,">=01/11/2025",'Livros Finalizados'!$I:$I,"<=30/11/2025") -> 3 | M29: Novembro | N29: =COUNTIFS('Livros Finalizados'!$I:$I,">=01/11/2026",'Livros Finalizados'!$I:$I,"<=30/11/2026") -> 0 | O29: Novembro | P29: =COUNTIFS('Livros Finalizados'!$I:$I,">=01/11/2027",'Livros Finalizados'!$I:$I,"<=30/11/2027") -> 0 | Q29: Novembro | S29: Novembro | U29: Novembro | V29: 0
C30: Dezembro | D30: =COUNTIFS('Livros Finalizados'!$I:$I,">=01/12/2021",'Livros Finalizados'!$I:$I,"<=31/12/2021") -> 0 | E30: Dezembro | F30: =COUNTIFS('Livros Finalizados'!$I:$I,">=01/12/2022",'Livros Finalizados'!$I:$I,"<=31/12/2022") -> 0 | G30: Dezembro | H30: =COUNTIFS('Livros Finalizados'!$I:$I,">=01/12/2023",'Livros Finalizados'!$I:$I,"<=31/12/2023") -> 0 | I30: Dezembro | J30: =COUNTIFS('Livros Finalizados'!$I:$I,">=01/12/2024",'Livros Finalizados'!$I:$I,"<=31/12/2024") -> 9 | K30: Dezembro | L30: =COUNTIFS('Livros Finalizados'!$I:$I,">=01/12/2025",'Livros Finalizados'!$I:$I,"<=31/12/2025") -> 6 | M30: Dezembro | N30: =COUNTIFS('Livros Finalizados'!$I:$I,">=01/12/2026",'Livros Finalizados'!$I:$I,"<=31/12/2026") -> 0 | O30: Dezembro | P30: =COUNTIFS('Livros Finalizados'!$I:$I,">=01/12/2027",'Livros Finalizados'!$I:$I,"<=31/12/2027") -> 0 | Q30: Dezembro | S30: Dezembro | U30: Dezembro | V30: 0
C31: Total | D31: =SUM(D19:D30) -> 1 | E31: Total | F31: =SUM(F19:F30) -> 7 | G31: Total | H31: =SUM(H19:H30) -> 0 | I31: Total | J31: =SUM(J19:J30) -> 72 | K31: Total | L31: =SUM(L19:L30) -> 36 | M31: Total | N31: =SUM(N19:N30) -> 27 | O31: Total | P31: =SUM(P19:P30) -> 0 | Q31: Total | R31: =SUM(R19:R30) -> 0 | S31: Total | T31: =SUM(T19:T30) -> 0 | U31: Total | V31: =SUM(V19:V30) -> 0

Sheet Biblioteca
A1: Nº | B1: Tipo | C1: Nome | D1: Autor | E1: Editora | F1: Ano | G1: Pág
J3: Ano | K3: Nº | M3: Tipo | N3: Nº
J4: 2011 | K4: =COUNTIFS(F:F,">=2011",F:F,"<=2011") -> 0 | M4: Livros | N4: =COUNTIFS(B:B,"Livro") -> 68
J5: 2012 | K5: =COUNTIFS(F:F,">=2012",F:F,"<=2012") -> 0 | M5: HQs | N5: =COUNTIFS(B:B,"HQ") -> 4
J6: 2013 | K6: =COUNTIFS(F:F,">=2013",F:F,"<=2013") -> 0 | M6: Mangás | N6: =COUNTIFS(B:B,"Mangá") -> 0
J7: 2014 | K7: =COUNTIFS(F:F,">=2014",F:F,"<=2014") -> 0 | M7: Total | N7: =SUM(N4:N6) -> 72
J8: 2015 | K8: =COUNTIFS(F:F,">=2015",F:F,"<=2015") -> 0 | M8: Total Pág | N8: =SUM(G:G) -> 31539
J9: 2016 | K9: =COUNTIFS(F:F,">=2016",F:F,"<=2016") -> 0
J10: 2017 | K10: =COUNTIFS(F:F,">=2017",F:F,"<=2017") -> 0
J11: 2018 | K11: =COUNTIFS(F:F,">=2018",F:F,"<=2018") -> 0
J12: 2019 | K12: =COUNTIFS(F:F,">=2019",F:F,"<=2019") -> 0
J13: 2020 | K13: =COUNTIFS(F:F,">=2020",F:F,"<=2020") -> 0
J14: 2021 | K14: =COUNTIFS(F:F,">=2021",F:F,"<=2021") -> 1
J15: 2022 | K15: =COUNTIFS(F:F,">=2022",F:F,"<=2022") -> 9
J16: 2023 | K16: =COUNTIFS(F:F,">=2023",F:F,"<=2023") -> 1
J17: 2024 | K17: =COUNTIFS(F:F,">=2024",F:F,"<=2024") -> 17
J18: 2025 | K18: =COUNTIFS(F:F,">=2025",F:F,"<=2025") -> 35
J19: 2026 | K19: =COUNTIFS(F:F,">=2026",F:F,"<=2026") -> 9
J20: Total | K20: =SUM(K4:K19) -> 72
A53: 72 | B53: Livro | C53: A arte da Guerra | D53: Sun Tzu | E53: Edipro | F53: 2022 | G53: 160
